<?xml version="1.0"?>
<!-- created with Phobos 1.0.1 "Capricious Choutengan" -->
  <robot name="unnamed">

    <link name="link_chest">
      <inertial>
        <origin xyz="-0.00181 0 0" rpy="0 0 0"/>
        <mass value="24.009"/>
        <inertia ixx="101.61387" ixy="0" ixz="0" iyy="4.82248" iyz="0" izz="104.30943"/>
      </inertial>
      <visual name="visual_chest">
        <origin xyz="0 0 0" rpy="0 -1.5708 0"/>
        <geometry>
          <box size="0.25 0.25 0.25"/>
        </geometry>
      </visual>
      <visual name="visual_leg0_0">
        <origin xyz="0 0.35 0" rpy="1.5708 -1.5708 0"/>
        <geometry>
          <mesh filename="../meshes/dae/visual.005.dae" scale="1.0 1.0 1.0"/>
        </geometry>
      </visual>
      <visual name="visual_leg0_1">
        <origin xyz="0 0.775 0" rpy="1.5708 -1.5708 0"/>
        <geometry>
          <mesh filename="../meshes/dae/visual.005.dae" scale="1.0 1.0 1.0"/>
        </geometry>
      </visual>
      <visual name="visual_leg0_2">
        <origin xyz="0 1.2 0" rpy="1.5708 -1.5708 0"/>
        <geometry>
          <mesh filename="../meshes/dae/visual.005.dae" scale="1.0 1.0 1.0"/>
        </geometry>
      </visual>
      <visual name="visual_leg0_foot">
        <origin xyz="-0.00771 1.4 0" rpy="0 -1.5708 0"/>
        <geometry>
          <sphere radius="0.09"/>
        </geometry>
      </visual>
      <visual name="visual_leg1_0">
        <origin xyz="0 -0.35 0" rpy="1.5708 -1.5708 0"/>
        <geometry>
          <mesh filename="../meshes/dae/visual.005.dae" scale="1.0 1.0 1.0"/>
        </geometry>
      </visual>
      <visual name="visual_leg1_1">
        <origin xyz="0 -0.775 0" rpy="1.5708 -1.5708 0"/>
        <geometry>
          <mesh filename="../meshes/dae/visual.005.dae" scale="1.0 1.0 1.0"/>
        </geometry>
      </visual>
      <visual name="visual_leg1_2">
        <origin xyz="0 -1.2 0" rpy="1.5708 -1.5708 0"/>
        <geometry>
          <mesh filename="../meshes/dae/visual.005.dae" scale="1.0 1.0 1.0"/>
        </geometry>
      </visual>
      <visual name="visual_leg1_foot">
        <origin xyz="-0.00771 -1.4 0" rpy="0 -1.5708 0"/>
        <geometry>
          <sphere radius="0.09"/>
        </geometry>
      </visual>
      <collision name="collision_chest">
        <origin xyz="0 0 0" rpy="0 -1.5708 0"/>
        <geometry>
          <box size="0.25 0.25 0.25"/>
        </geometry>
      </collision>
      <collision name="collision_leg0_0">
        <origin xyz="0 0.35 0" rpy="1.5708 -1.5708 0"/>
        <geometry>
          <cylinder radius="0.06728" length="0.4"/>
        </geometry>
      </collision>
      <collision name="collision_leg0_1">
        <origin xyz="0 0.775 0" rpy="1.5708 -1.5708 0"/>
        <geometry>
          <cylinder radius="0.06728" length="0.4"/>
        </geometry>
      </collision>
      <collision name="collision_leg0_2">
        <origin xyz="0 1.2 0" rpy="1.5708 -1.5708 0"/>
        <geometry>
          <cylinder radius="0.06728" length="0.4"/>
        </geometry>
      </collision>
      <collision name="collision_leg0_foot">
        <origin xyz="-0.00771 1.4 0" rpy="0 -1.5708 0"/>
        <geometry>
          <sphere radius="0.09"/>
        </geometry>
      </collision>
      <collision name="collision_leg1_0">
        <origin xyz="0 -0.35 0" rpy="1.5708 -1.5708 0"/>
        <geometry>
          <cylinder radius="0.06728" length="0.4"/>
        </geometry>
      </collision>
      <collision name="collision_leg1_1">
        <origin xyz="0 -0.775 0" rpy="1.5708 -1.5708 0"/>
        <geometry>
          <cylinder radius="0.06728" length="0.4"/>
        </geometry>
      </collision>
      <collision name="collision_leg1_2">
        <origin xyz="0 -1.2 0" rpy="1.5708 -1.5708 0"/>
        <geometry>
          <cylinder radius="0.06728" length="0.4"/>
        </geometry>
      </collision>
      <collision name="collision_leg1_foot">
        <origin xyz="-0.00771 -1.4 0" rpy="0 -1.5708 0"/>
        <geometry>
          <sphere radius="0.09"/>
        </geometry>
      </collision>
    </link>

    <link name="link_hip">
      <inertial>
        <origin xyz="0.00148 0 0.00118" rpy="0 0 0"/>
        <mass value="24.009"/>
        <inertia ixx="68.00676" ixy="0" ixz="-0.00046" iyy="3.10928" iyz="0" izz="69.81373"/>
      </inertial>
      <visual name="visual_hip">
        <origin xyz="0 0 0" rpy="0 1.5708 0"/>
        <geometry>
          <box size="0.25 0.25 0.25"/>
        </geometry>
      </visual>
      <visual name="visual_leg2_0">
        <origin xyz="0 0.35 0" rpy="1.5708 1.5708 0"/>
        <geometry>
          <mesh filename="../meshes/dae/visual.005.dae" scale="1.0 1.0 1.0"/>
        </geometry>
      </visual>
      <visual name="visual_leg2_0.001">
        <origin xyz="0 0.775 0" rpy="1.5708 1.5708 0"/>
        <geometry>
          <mesh filename="../meshes/dae/visual.005.dae" scale="1.0 1.0 1.0"/>
        </geometry>
      </visual>
      <visual name="visual_leg2_0.002">
        <origin xyz="0 1.2 0" rpy="1.5708 1.5708 0"/>
        <geometry>
          <mesh filename="../meshes/dae/visual.005.dae" scale="1.0 1.0 1.0"/>
        </geometry>
      </visual>
      <visual name="visual_leg2_foot">
        <origin xyz="0.00771 1.4 0.00613" rpy="0 1.5708 0"/>
        <geometry>
          <sphere radius="0.09"/>
        </geometry>
      </visual>
      <visual name="visual_leg3_0">
        <origin xyz="0 -0.35 0" rpy="1.5708 1.5708 0"/>
        <geometry>
          <mesh filename="../meshes/dae/visual.005.dae" scale="1.0 1.0 1.0"/>
        </geometry>
      </visual>
      <visual name="visual_leg3_1">
        <origin xyz="0 -0.775 0" rpy="1.5708 1.5708 0"/>
        <geometry>
          <mesh filename="../meshes/dae/visual.005.dae" scale="1.0 1.0 1.0"/>
        </geometry>
      </visual>
      <visual name="visual_leg3_2">
        <origin xyz="0 -1.2 0" rpy="1.5708 1.5708 0"/>
        <geometry>
          <mesh filename="../meshes/dae/visual.005.dae" scale="1.0 1.0 1.0"/>
        </geometry>
      </visual>
      <visual name="visual_leg3_foot">
        <origin xyz="0.00771 -1.4 0.00613" rpy="0 1.5708 0"/>
        <geometry>
          <sphere radius="0.09"/>
        </geometry>
      </visual>
      <collision name="collision_hip">
        <origin xyz="0 0 0" rpy="0 1.5708 0"/>
        <geometry>
          <box size="0.25 0.25 0.25"/>
        </geometry>
      </collision>
      <collision name="collision_leg2_0">
        <origin xyz="0 0.35 0" rpy="1.5708 1.5708 0"/>
        <geometry>
          <cylinder radius="0.06728" length="0.4"/>
        </geometry>
      </collision>
      <collision name="collision_leg2_0.001">
        <origin xyz="0 0.775 0" rpy="1.5708 1.5708 0"/>
        <geometry>
          <cylinder radius="0.06728" length="0.4"/>
        </geometry>
      </collision>
      <collision name="collision_leg2_0.002">
        <origin xyz="0 1.2 0" rpy="1.5708 1.5708 0"/>
        <geometry>
          <cylinder radius="0.06728" length="0.4"/>
        </geometry>
      </collision>
      <collision name="collision_leg2_foot">
        <origin xyz="0.00771 1.4 0.00613" rpy="0 1.5708 0"/>
        <geometry>
          <sphere radius="0.09"/>
        </geometry>
      </collision>
      <collision name="collision_leg3_0">
        <origin xyz="0 -0.35 0" rpy="1.5708 1.5708 0"/>
        <geometry>
          <cylinder radius="0.06728" length="0.4"/>
        </geometry>
      </collision>
      <collision name="collision_leg3_1">
        <origin xyz="0 -0.775 0" rpy="1.5708 1.5708 0"/>
        <geometry>
          <cylinder radius="0.06728" length="0.4"/>
        </geometry>
      </collision>
      <collision name="collision_leg3_2">
        <origin xyz="0 -1.2 0" rpy="1.5708 1.5708 0"/>
        <geometry>
          <cylinder radius="0.06728" length="0.4"/>
        </geometry>
      </collision>
      <collision name="collision_leg3_foot">
        <origin xyz="0.00771 -1.4 0.00613" rpy="0 1.5708 0"/>
        <geometry>
          <sphere radius="0.09"/>
        </geometry>
      </collision>
    </link>

    <link name="link_left_eye">
      <inertial>
        <origin xyz="0 0 0" rpy="0 0 0"/>
        <mass value="0.001"/>
        <inertia ixx="0.001" ixy="0" ixz="0" iyy="0.001" iyz="0" izz="0.001"/>
      </inertial>
    </link>

    <link name="link_neck">
      <inertial>
        <origin xyz="0 0 0.29855" rpy="0 0 0"/>
        <mass value="3.502"/>
        <inertia ixx="0.63283" ixy="0" ixz="0" iyy="0.4556" iyz="0" izz="0.26017"/>
      </inertial>
      <visual name="visual_eye_left">
        <origin xyz="0.1036 0.15 0.27695" rpy="-3.14159 -1.5708 0"/>
        <geometry>
          <mesh filename="../meshes/dae/Cylinder.001.dae" scale="1.0 1.0 1.0"/>
        </geometry>
        <material name="Material.001"/>
      </visual>
      <visual name="visual_eye_right">
        <origin xyz="0.1036 -0.15 0.27695" rpy="-3.14159 -1.5708 0"/>
        <geometry>
          <mesh filename="../meshes/dae/Cylinder.002.dae" scale="1.0 1.0 1.0"/>
        </geometry>
        <material name="Material.001"/>
      </visual>
      <visual name="visual_head">
        <origin xyz="0 0 0.28709" rpy="0 0 0"/>
        <geometry>
          <box size="0.20869 0.6038 0.16987"/>
        </geometry>
      </visual>
      <visual name="visual_neck">
        <origin xyz="0 0 0" rpy="0 0 0"/>
        <geometry>
          <cylinder radius="0.07209" length="0.60833"/>
        </geometry>
      </visual>
      <collision name="collision_head">
        <origin xyz="0 0 0.28709" rpy="0 0 0"/>
        <geometry>
          <box size="0.20869 0.6038 0.16987"/>
        </geometry>
      </collision>
      <collision name="collision_neck">
        <origin xyz="0 0 0" rpy="0 0 0"/>
        <geometry>
          <cylinder radius="0.07209" length="0.60833"/>
        </geometry>
      </collision>
    </link>

    <link name="link_right_eye">
      <inertial>
        <origin xyz="0 0 0" rpy="0 0 0"/>
        <mass value="0.001"/>
        <inertia ixx="0.001" ixy="0" ixz="0" iyy="0.001" iyz="0" izz="0.001"/>
      </inertial>
    </link>

    <link name="root">
      <inertial>
        <origin xyz="0 0 0" rpy="0 0 0"/>
        <mass value="10.001"/>
        <inertia ixx="1.9331" ixy="0" ixz="0" iyy="1.9331" iyz="0" izz="2.56142"/>
      </inertial>
      <visual name="visual_body">
        <origin xyz="0 0 0" rpy="0 0 0"/>
        <geometry>
          <cylinder radius="0.325" length="0.4"/>
        </geometry>
      </visual>
      <collision name="collision_body">
        <origin xyz="0 0 0" rpy="0 1.5708 0"/>
        <geometry>
          <cylinder radius="0.2" length="0.65"/>
        </geometry>
      </collision>
    </link>

    <joint name="link_chest" type="floating">
      <origin xyz="0.44839 0.00518 -0.01418" rpy="0 1.5708 0"/>
      <parent link="root"/>
      <child link="link_chest"/>
    </joint>

    <joint name="link_hip" type="floating">
      <origin xyz="-0.45161 0.00518 -0.01418" rpy="0 -1.5708 0"/>
      <parent link="root"/>
      <child link="link_hip"/>
    </joint>

    <joint name="link_left_eye" type="floating">
      <origin xyz="0.11704 0.15288 0.28304" rpy="1.5708 0 -1.5708"/>
      <parent link="link_neck"/>
      <child link="link_left_eye"/>
    </joint>

    <joint name="link_neck" type="revolute">
      <origin xyz="0.44839 0.00518 0.29152" rpy="0 0 0"/>
      <parent link="root"/>
      <child link="link_neck"/>
      <axis xyz="0 0 1.0"/>
      <limit lower="-1.5708" upper="1.5708" effort="0" velocity="0"/>
    </joint>

    <joint name="link_right_eye" type="floating">
      <origin xyz="0.11923 -0.14892 0.28171" rpy="1.5708 0 -1.5708"/>
      <parent link="link_neck"/>
      <child link="link_right_eye"/>
    </joint>

    <material name="Material.001">
      <color rgba="0 0 0 1.0"/>
    </material>

  </robot>
